try {
  console.log('Внутри try до myWar');

  myWar;

  console.log('Внутри try после myWar');
} catch {
  console.log('Error!');
}

console.log('После try ... catch');
    
